Downloading data from https://storage.googleapis.com/tensorflow/tf-keras-datasets/train-labels-idx1-ubyte.gz
 8192/29515 [=======>......................] - ETA: 0s32768/29515 [=================================] - 0s 0us/step
Downloading data from https://storage.googleapis.com/tensorflow/tf-keras-datasets/train-images-idx3-ubyte.gz
    8192/26421880 [..............................] - ETA: 0s 5488640/26421880 [=====>........................] - ETA: 0s10633216/26421880 [===========>..................] - ETA: 0s15400960/26421880 [================>.............] - ETA: 0s21012480/26421880 [======================>.......] - ETA: 0s26427392/26421880 [==============================] - 0s 0us/step
Downloading data from https://storage.googleapis.com/tensorflow/tf-keras-datasets/t10k-labels-idx1-ubyte.gz
8192/5148 [===============================================] - 0s 0us/step
Downloading data from https://storage.googleapis.com/tensorflow/tf-keras-datasets/t10k-images-idx3-ubyte.gz
   8192/4422102 [..............................] - ETA: 0s4423680/4422102 [==============================] - 0s 0us/step
WARNING:tensorflow:From /opt/conda/lib/python3.7/site-packages/tensorflow/python/ops/resource_variable_ops.py:435: colocate_with (from tensorflow.python.framework.ops) is deprecated and will be removed in a future version.
Instructions for updating:
Colocations handled automatically by placer.
Traceback (most recent call last):
  File "fashion_train.py", line 57, in <module>
    callbacks=[WandbCallback(data_type="image", labels=labels)])
  File "/opt/conda/lib/python3.7/site-packages/tensorflow/python/keras/engine/training.py", line 776, in fit
    shuffle=shuffle)
  File "/opt/conda/lib/python3.7/site-packages/tensorflow/python/keras/engine/training.py", line 2382, in _standardize_user_data
    exception_prefix='input')
  File "/opt/conda/lib/python3.7/site-packages/tensorflow/python/keras/engine/training_utils.py", line 353, in standardize_input_data
    'with shape ' + str(data_shape))
ValueError: Error when checking input: expected flatten_input to have 4 dimensions, but got array with shape (60000, 28, 28)
